Workbook

Sheet Leeme
A2: Backtest - Modelo de factores macro Oil & Gas vs Merval
A4: ORDEN DE LAS HOJAS
A5: Base Datos crudos. Columnas A:T copiadas de tu archivo; columna U (Brent) descargada de FRED. Todo en AZUL = entrada.
A6: Transf Los 8 factores "Exc." Replica tus formulas, con el signo de inventarios corregido.
A7: Senal Normalizacion z expansiva, winsorizacion Tukey point-in-time, mediana, umbral y senal.
A8: Backtest Beta a Brent, retorno cubierto, escalera de 12 tramos, P&L, drawdown y retornos forward.
A9: Resumen Metricas, IC y la lectura de hoy. Los parametros editables estan en AMARILLO.
A11: CODIGO DE COLORES
A12: AZUL dato de entrada (hardcodeado)
A13: NEGRO formula
A14: VERDE referencia a otra hoja
A15: AMARILLO parametro que podes cambiar
... A41: 5. Se saco la brecha cambiaria (no es una variable continua: 24% de los meses en cero y solo dos episodios de cepo en la muestra).

Sheet Base
A1: Fecha | B1: Exp nivel | C1: Exp yoy % | D1: Impo | E1: PBI nominal | F1: (Exp+Imp)/PBI | G1: EMAE yoy % | H1: EMAE Transp yoy % | I1: IPC Transp yoy % | J1: Prod. petroleo Arg | K1: Prod. petroleo yoy % | L1: ITCRM | M1: ITCRM yoy % | N1: Invent. crudo EEUU | O1: Invent. crudo yoy % | P1: Crack spread yoy % | Q1: PBI yoy % | R1: PBI prom 5A | S1: REM 12M | T1: Ratio O&G/Merval | U1: Brent (USD/bbl)
A2: 38017 | B2: 2322 | D2: 1609 | G2: 10.2 | I2: -0.40792348 | J2: 701.755 | L2: 159.536 | N2: 255245 | P2: 3.7609948
A3: 38046 | B3: 2395 | D3: 1364 | G3: 10.2 | I3: -0.92311906 | J3: 706.096 | L3: 159.629 | N3: 259092 | P3: -8.5377611
A4: 38077 | B4: 2658 | D4: 1690 | E4: 151.11 | G4: 13.2 | I4: -0.90675726 | J4: 683.964 | L4: 155.118 | N4: 277539 | P4: 30.716359
A5: 38107 | B5: 3040 | D5: 1651 | E5: 151.11 | G5: 6.8 | I5: -0.031656771 | J5: 679.854 | L5: 151.165 | N5: 282748 | P5: 72.362556
A6: 38138 | B6: 3394 | D6: 1792 | E6: 151.11 | G6: 5.9 | I6: 1.0678588 | J6: 712.11 | L6: 155.047 | N6: 285384 | P6: 112.77349
A7: 38168 | B7: 2951 | D7: 2039 | E7: 175.44 | G7: 8.8 | I7: 1.9446521 | J7: 707.394 | L7: 154.076 | N7: 288862 | P7: 89.060415
A8: 38199 | B8: 3034 | D8: 1970 | E8: 175.44 | G8: 7.3 | I8: 1.9590982 | J8: 696.371 | L8: 156.135 | N8: 282564 | P8: 65.281307
A9: 38230 | B9: 2945 | D9: 2032 | E9: 175.44 | G9: 10.1 | I9: 2.3238328 | J9: 688.71 | L9: 159.947 | N9: 271284 | P9: -8.4836339
A10: 38260 | B10: 3002 | D10: 2025 | E10: 163.49 | G10: 8.9 | I10: 2.9918852 | J10: 706.017 | L10: 160.499 | N10: 257031 | P10: 60.26796
A11: 38291 | B11: 2831 | D11: 1973 | E11: 163.49 | G11: 7.3 | I11: 2.7729906 | J11: 698.292 | L11: 161.079 | N11: 273529 | P11: 35.999083
A12: 38321 | B12: 3042 | D12: 2193 | E12: 163.49 | G12: 10.9 | I12: 2.4934673 | J12: 675.486 | L12: 165.003 | N12: 276981 | P12: 40.917702
A13: 38352 | B13: 2962 | D13: 2109 | E13: 169.79 | F13: 0.33584428 | G13: 9.6 | I13: 3.2049911 | J13: 682.534 | L13: 169.353 | N13: 275442 | P13: -9.3349984
A14: 38383 | B14: 2781 | C14: 19.767442 | D14: 1901 | E14: 169.79 | F14: 0.34026739 | G14: 6.3 | H14: 12.3 | I14: 4.4088634 | J14: 678.684 | K14: -3.2876146 | L14: 163.055 | M14: 2.2057717 | N14: 279566 | O14: 9.5284922 | P14: 22.858813
A15: 38411 | B15: 2606 | C15: 8.8100209 | D15: 1867 | E15: 169.79 | F15: 0.34447258 | G15: 6.6 | H15: 12.4 | I15: 5.391405 | J15: 678.364 | K15: -3.9275113 | L15: 164.581 | M15: 3.1021932 | N15: 283301 | O15: 9.3437852 | P15: -4.6732256
A16: 38442 | B16: 3054 | C16: 14.89842 | D16: 2198 | E16: 174.34 | F16: 0.34066766 | G16: 8.6 | H16: 14.4 | I16: 6.4800433 | J16: 676.981 | K16: -1.0209602 | L16: 158.604 | M16: 2.2473214 | N16: 298349 | O16: 7.4980453 | P16: 61.159149 | Q16: 7.2
A17: 38472 | B17: 3561 | C17: 17.138158 | D17: 2380 | E17: 174.34 | F17: 0.34783756 | G17: 13.6 | H17: 15.6 | I17: 6.0567796 | J17: 677.515 | K17: -0.34404446 | L17: 161.298 | M17: 6.7032713 | N17: 311127 | O17: 10.036853 | P17: 16.216475 | Q17: 7.2
A18: 38503 | B18: 3695 | C18: 8.8685916 | D18: 2476 | E18: 174.34 | F18: 0.35348744 | G18: 15.3 | H18: 17.8 | I18: 6.059606 | J18: 682.57 | K18: -4.1482355 | L18: 160.255 | M18: 3.3589815 | N18: 317706 | O18: 11.325793 | P18: -7.9522084 | Q18: 7.2
A19: 38533 | B19: 3450 | C19: 16.909522 | D19: 2724 | E19: 209.55 | F19: 0.2997423 | G19: 10.3 | H19: 16.5 | I19: 6.3155492 | J19: 671.959 | K19: -5.0092311 | L19: 159.909 | M19: 3.785794 | N19: 312453 | O19: 8.1668755 | P19: 3.3064516 | Q19: 13.1
A20: 38564 | B20: 3601 | C20: 18.6882 | D20: 2349 | E20: 209.55 | F20: 0.30425674 | G20: 6.4 | H20: 16.6 | I20: 6.9467413 | J20: 671.923 | K20: -3.5107723 | L20: 157.442 | M20: 0.8370961 | N20: 302036 | O20: 6.8911822 | P20: 23.289777 | Q20: 13.1
A21: 38595 | B21: 3837 | C21: 30.288625 | D21: 2626 | E21: 209.55 | F21: 0.31134813 | G21: 7.6 | H21: 16.3 | I21: 7.0561613 | J21: 666.511 | K21: -3.2232725 | L21: 161.454 | M21: 0.9421871 | N21: 305363 | O21: 12.562112 | P21: 324.79927 | Q21: 13.1
A22: 38625 | B22: 3483 | C22: 16.022652 | D22: 2468 | E22: 204.28 | F22: 0.32390347 | G22: 6.9 | H22: 15.9 | I22: 7.6813306 | J22: 645.615 | K22: -8.5553181 | L22: 162.7 | M22: 1.3713481 | N22: 289398 | O22: 12.592644 | P22: 221.20208 | Q22: 7
A23: 38656 | B23: 3399 | C23: 20.063582 | D23: 2503 | E23: 204.28 | F23: 0.32927844 | G23: 6.8 | H23: 14.7 | I23: 8.132387 | J23: 623.582 | K23: -10.698963 | L23: 166.021 | M23: 3.0680598 | N23: 303027 | O23: 10.784231 | P23: 73.496209 | Q23: 7
A24: 38686 | B24: 3274 | C24: 7.6265615 | D24: 2701 | E24: 204.28 | F24: 0.33290092 | G24: 7.9 | H24: 12.4 | I24: 9.5727506 | J24: 650.316 | K24: -3.726206 | L24: 163.367 | M24: -0.99149712 | N24: 301443 | O24: 8.8316527 | P24: 23.300971 | Q24: 7
A25: 38717 | B25: 3645 | C25: 23.058744 | D25: 2495 | E25: 209.23 | F25: 0.3301343 | G25: 8.7 | H25: 14 | I25: 9.8985781 | J25: 653.195 | K25: -4.2985404 | L25: 162.511 | M25: -4.040082 | N25: 305527 | O25: 10.922445 | P25: 108.4022 | Q25: 7.8
A26: 38748 | B26: 3188 | C26: 14.635023 | D26: 2324 | E26: 209.23 | F26: 0.33410123 | G26: 8.2 | H26: 12.4 | I26: 9.6562073 | J26: 648.863 | K26: -4.3939448 | L26: 167.111 | M26: 2.4875042 | N26: 304935 | O26: 9.0744225 | P26: 1.034975 | Q26: 7.8
A27: 38776 | B27: 3090 | C27: 18.572525 | D27: 2326 | E27: 209.23 | F27: 0.33860823 | G27: 8.3 | H27: 13.9 | I27: 8.9925922 | J27: 629.005 | K27: -7.2761821 | L27: 169.294 | M27: 2.8636355 | N27: 312135 | O27: 10.177867 | P27: -11.008723 | Q27: 7.8
... A38: 39113 | B38: 3390 | C38: 6.336261 | D38: 2951 | E38: 247.8 | F38: 0.32900323 | G38: 7.7 | H38: 13.3 | I38: 5.1336095 | J38: 652.861 | K38: 0.61615472 | L38: 163.081 | M38: -2.4115708 | N38: 307711 | O38: 0.91035795 | P38: 4.7921818 | Q38: 9.7
A39: 39141 | B39: 3587 | C39: 16.084142 | D39: 2791 | E39: 247.8 | F39: 0.33288539 | G39: 8.3 | H39: 12.6 | I39: 5.6748822 | J39: 654.151 | K39: 3.9977425 | L39: 163.327 | M39: -3.5246376 | N39: 311719 | O39: -0.13327567 | P39: 114.96617 | Q39: 9.7 | R39: 8.45
A40: 39172 | B40: 4173 | C40: 14.391447 | D40: 3422 | E40: 250.14 | F40: 0.33466859 | G40: 9 | H40: 13.3 | I40: 5.9315225 | J40: 658.454 | K40: -0.18206487 | L40: 164.445 | M40: -1.4053685 | N40: 315387 | O40: -3.3865128 | P40: 47.589425 | Q40: 8.4 | R40: 8.448
A41: 39202 | B41: 4299 | C41: 9.5286624 | D41: 3061 | E41: 250.14 | F41: 0.33822659 | G41: 9.3 | H41: 13.5 | I41: 7.9107545 | J41: 666.882 | K41: 1.090209 | L41: 162.919 | M41: -3.2196936 | N41: 318468 | O41: -3.5789869 | P41: 62.724693 | Q41: 8.4 | R41: 8.4461538
A42: 39233 | B42: 4856 | C42: 16.144463 | D42: 3542 | E42: 250.14 | F42: 0.34378748 | G42: 10.7 | H42: 14.4 | I42: 9.9768223 | J42: 663.095 | K42: -0.9531335 | L42: 162.155 | M42: -1.1707989 | N42: 325014 | O42: -1.2568699 | P42: 56.897677 | Q42: 8.4 | R42: 8.4444444
A43: 39263 | B43: 4521 | C43: 17.489605 | D43: 3579 | E43: 293.29 | F43: 0.29795765 | G43: 9.5 | H43: 14.3 | I43: 12.546611 | J43: 655.071 | K43: -2.9728561 | L43: 159.444 | M43: -4.5308393 | N43: 336924 | O43: 3.6405415 | P43: 24.793637 | Q43: 9.9 | R43: 8.4964286
A44: 39294 | B44: 4614 | C44: 20.880272 | D44: 4126 | E44: 293.29 | F44: 0.30501892 | G44: 8.8 | H44: 13.6 | I44: 15.313295 | J44: 632.482 | K44: -5.8949386 | L44: 159.679 | M44: -3.5382032 | N44: 327287 | O44: 3.061096 | P44: -34.732515 | Q44: 9.9 | R44: 8.5448276
A45: 39325 | B45: 4922 | C45: 15.920867 | D45: 4606 | E45: 293.29 | F45: 0.31184152 | G45: 8.8 | H45: 12.1 | I45: 19.249919 | J45: 655.962 | K45: -1.4700736 | L45: 154.497 | M45: -7.6797591 | N45: 312591 | O45: -1.2696969 | P45: 24.031992 | Q45: 9.9 | R45: 8.59
A46: 39355 | B46: 4828 | C46: 19.268775 | D46: 3963 | E46: 291.46 | F46: 0.31919989 | G46: 7.6 | H46: 10.5 | I46: 21.298396 | J46: 663.274 | K46: -2.4152187 | L46: 157.525 | M46: -4.6372249 | N46: 304684 | O46: -2.3451848 | P46: 29.156954 | Q46: 8.4 | R46: 8.583871
A47: 39386 | B47: 5581 | C47: 32.75452 | D47: 4400 | E47: 291.46 | F47: 0.32785288 | G47: 10.2 | H47: 12.7 | I47: 22.52987 | J47: 658.56 | K47: -2.8189528 | L47: 159.438 | M47: -3.136676 | N47: 295477 | O47: -7.040902 | P47: 38.145232 | Q47: 8.4 | R47: 8.578125
A48: 39416 | B48: 5424 | C48: 31.970803 | D48: 4384 | E48: 291.46 | F48: 0.33629658 | G48: 9.8 | H48: 11 | I48: 20.624128 | J48: 622.965 | K48: -0.69628092 | L48: 159.413 | M48: -2.4406215 | N48: 287895 | O48: -11.268947 | P48: -5.596543 | Q48: 8.4 | R48: 8.5727273
A49: 39447 | B49: 5787 | C49: 36.453667 | D49: 3881 | E49: 316.38 | F49: 0.31825021 | G49: 7.8 | H49: 11 | I49: 19.783908 | J49: 654.397 | K49: -1.1592395 | L49: 159.57 | M49: -1.9798149 | N49: 271865 | O49: -10.340381 | P49: 49.07293 | Q49: 9.3 | R49: 8.5941176
A50: 39478 | B50: 5818 | C50: 71.622419 | D50: 4479 | E50: 316.38 | F50: 0.33075416 | G50: 10 | H50: 11.4 | I50: 20.956813 | J50: 665.363 | K50: 1.9149559 | L50: 159.852 | M50: -1.9799977 | N50: 275472 | O50: -10.477039 | P50: 8.5280899 | Q50: 9.3 | R50: 8.6142857
...

Sheet Transf
A1: Fecha | B1: Exc. Exp | C1: Exc. EMAE | D1: Exc. EMAE Transp | E1: Exc. IPC Transp | F1: Exc. Prod. petroleo | G1: Exc. ITCRM | H1: Exc. Invent. (signo inv.) | I1: Exc. Crack spread
A2: =Base!A2 -> 38017
A3: =Base!A3 -> 38046
A4: =Base!A4 -> 38077
A5: =Base!A5 -> 38107
A6: =Base!A6 -> 38138
A7: =Base!A7 -> 38168
A8: =Base!A8 -> 38199
A9: =Base!A9 -> 38230
A10: =Base!A10 -> 38260
A11: =Base!A11 -> 38291
A12: =Base!A12 -> 38321
A13: =Base!A13 -> 38352
... A38: =Base!A38 -> 39113
A39: =Base!A39 -> 39141 | B39: =IFERROR(AVERAGE(Base!C37:C39)-Base!R39,"") -> 4.4738565 | C39: =IFERROR(AVERAGE(Base!G37:G39)-Base!R39,"") -> -0.38333333 | D39: =IFERROR(AVERAGE(Base!H37:H39)-Base!R39,"") -> 4.35 | E39: -7.6415495 | F39: =IFERROR(AVERAGE(Base!K37:K39),"") -> 1.9909698 | G39: =IFERROR(AVERAGE(Base!M37:M39)*AVERAGE(Base!$F$13:F39),"") -> -0.63539272 | H39: =IFERROR(-AVERAGE(Base!O37:O39),"") -> -0.0072220758 | I39: =IFERROR(AVERAGE(Base!P37:P39),"") -> 26.637341
A40: =Base!A40 -> 39172 | B40: =IFERROR(AVERAGE(Base!C38:C40)-Base!R40,"") -> 3.8226169 | C40: =IFERROR(AVERAGE(Base!G38:G40)-Base!R40,"") -> -0.11466667 | D40: =IFERROR(AVERAGE(Base!H38:H40)-Base!R40,"") -> 4.6186667 | E40: -7.4665241 | F40: =IFERROR(AVERAGE(Base!K38:K40),"") -> 1.4772774 | G40: =IFERROR(AVERAGE(Base!M38:M40)*AVERAGE(Base!$F$13:F40),"") -> -0.80982144 | H40: =IFERROR(-AVERAGE(Base!O38:O40),"") -> 0.86981016 | I40: =IFERROR(AVERAGE(Base!P38:P40),"") -> 55.782594
A41: =Base!A41 -> 39202 | B41: =IFERROR(AVERAGE(Base!C39:C41)-Base!R41,"") -> 4.8885969 | C41: =IFERROR(AVERAGE(Base!G39:G41)-Base!R41,"") -> 0.42051282 | D41: =IFERROR(AVERAGE(Base!H39:H41)-Base!R41,"") -> 4.6871795 | E41: -6.8069323 | F41: =IFERROR(AVERAGE(Base!K39:K41),"") -> 1.6352955 | G41: =IFERROR(AVERAGE(Base!M39:M41)*AVERAGE(Base!$F$13:F41),"") -> -0.89964698 | H41: =IFERROR(-AVERAGE(Base!O39:O41),"") -> 2.3662584 | I41: =IFERROR(AVERAGE(Base!P39:P41),"") -> 75.09343
A42: =Base!A42 -> 39233 | B42: =IFERROR(AVERAGE(Base!C40:C42)-Base!R42,"") -> 4.9104132 | C42: =IFERROR(AVERAGE(Base!G40:G42)-Base!R42,"") -> 1.2222222 | D42: =IFERROR(AVERAGE(Base!H40:H42)-Base!R42,"") -> 5.2888889 | E42: -5.9382206 | F42: =IFERROR(AVERAGE(Base!K40:K42),"") -> -0.014996442 | G42: =IFERROR(AVERAGE(Base!M40:M42)*AVERAGE(Base!$F$13:F42),"") -> -0.64061876 | H42: =IFERROR(-AVERAGE(Base!O40:O42),"") -> 2.7407899 | I42: =IFERROR(AVERAGE(Base!P40:P42),"") -> 55.737265
A43: =Base!A43 -> 39263 | B43: =IFERROR(AVERAGE(Base!C41:C43)-Base!R43,"") -> 5.8911482 | C43: =IFERROR(AVERAGE(Base!G41:G43)-Base!R43,"") -> 1.3369048 | D43: =IFERROR(AVERAGE(Base!H41:H43)-Base!R43,"") -> 5.5702381 | E43: -4.1903499 | F43: =IFERROR(AVERAGE(Base!K41:K43),"") -> -0.94526018 | G43: =IFERROR(AVERAGE(Base!M41:M43)*AVERAGE(Base!$F$13:F43),"") -> -0.98285185 | H43: =IFERROR(-AVERAGE(Base!O41:O43),"") -> 0.39843844 | I43: =IFERROR(AVERAGE(Base!P41:P43),"") -> 48.138669
A44: =Base!A44 -> 39294 | B44: =IFERROR(AVERAGE(Base!C42:C44)-Base!R44,"") -> 9.6266192 | C44: =IFERROR(AVERAGE(Base!G42:G44)-Base!R44,"") -> 1.1218391 | D44: =IFERROR(AVERAGE(Base!H42:H44)-Base!R44,"") -> 5.5551724 | E44: -2.2697628 | F44: =IFERROR(AVERAGE(Base!K42:K44),"") -> -3.2736427 | G44: =IFERROR(AVERAGE(Base!M42:M44)*AVERAGE(Base!$F$13:F44),"") -> -1.0154885 | H44: =IFERROR(-AVERAGE(Base!O42:O44),"") -> -1.8149225 | I44: =IFERROR(AVERAGE(Base!P42:P44),"") -> 15.652933
A45: =Base!A45 -> 39325 | B45: =IFERROR(AVERAGE(Base!C43:C45)-Base!R45,"") -> 9.5069147 | C45: =IFERROR(AVERAGE(Base!G43:G45)-Base!R45,"") -> 0.44333333 | D45: =IFERROR(AVERAGE(Base!H43:H45)-Base!R45,"") -> 4.7433333 | E45: 0.21557915 | F45: =IFERROR(AVERAGE(Base!K43:K45),"") -> -3.4459561 | G45: =IFERROR(AVERAGE(Base!M43:M45)*AVERAGE(Base!$F$13:F45),"") -> -1.7280019 | H45: =IFERROR(-AVERAGE(Base!O43:O45),"") -> -1.8106469 | I45: =IFERROR(AVERAGE(Base!P43:P45),"") -> 4.6977046
A46: =Base!A46 -> 39355 | B46: =IFERROR(AVERAGE(Base!C44:C46)-Base!R46,"") -> 10.1061 | C46: =IFERROR(AVERAGE(Base!G44:G46)-Base!R46,"") -> -0.18387097 | D46: =IFERROR(AVERAGE(Base!H44:H46)-Base!R46,"") -> 3.4827957 | E46: 2.5993052 | F46: =IFERROR(AVERAGE(Base!K44:K46),"") -> -3.2600769 | G46: =IFERROR(AVERAGE(Base!M44:M46)*AVERAGE(Base!$F$13:F46),"") -> -1.7381253 | H46: =IFERROR(-AVERAGE(Base!O44:O46),"") -> 0.18459524 | I46: =IFERROR(AVERAGE(Base!P44:P46),"") -> 6.1521435
A47: =Base!A47 -> 39386 | B47: =IFERROR(AVERAGE(Base!C45:C47)-Base!R47,"") -> 14.069929 | C47: =IFERROR(AVERAGE(Base!G45:G47)-Base!R47,"") -> 0.28854167 | D47: =IFERROR(AVERAGE(Base!H45:H47)-Base!R47,"") -> 3.1885417 | E47: 4.3912161 | F47: =IFERROR(AVERAGE(Base!K45:K47),"") -> -2.2347483 | G47: =IFERROR(AVERAGE(Base!M45:M47)*AVERAGE(Base!$F$13:F47),"") -> -1.6939575 | H47: =IFERROR(-AVERAGE(Base!O45:O47),"") -> 3.5519279 | I47: =IFERROR(AVERAGE(Base!P45:P47),"") -> 30.444726
A48: =Base!A48 -> 39416 | B48: =IFERROR(AVERAGE(Base!C46:C48)-Base!R48,"") -> 19.425305 | C48: =IFERROR(AVERAGE(Base!G46:G48)-Base!R48,"") -> 0.62727273 | D48: =IFERROR(AVERAGE(Base!H46:H48)-Base!R48,"") -> 2.8272727 | E48: 4.4906806 | F48: =IFERROR(AVERAGE(Base!K46:K48),"") -> -1.9768175 | G48: =IFERROR(AVERAGE(Base!M46:M48)*AVERAGE(Base!$F$13:F48),"") -> -1.1203725 | H48: =IFERROR(-AVERAGE(Base!O46:O48),"") -> 6.8850113 | I48: =IFERROR(AVERAGE(Base!P46:P48),"") -> 20.568548
A49: =Base!A49 -> 39447 | B49: =IFERROR(AVERAGE(Base!C47:C49)-Base!R49,"") -> 25.132212 | C49: =IFERROR(AVERAGE(Base!G47:G49)-Base!R49,"") -> 0.67254902 | D49: =IFERROR(AVERAGE(Base!H47:H49)-Base!R49,"") -> 2.972549 | E49: 3.6169283 | F49: =IFERROR(AVERAGE(Base!K47:K49),"") -> -1.5581577 | G49: =IFERROR(AVERAGE(Base!M47:M49)*AVERAGE(Base!$F$13:F49),"") -> -0.82816097 | H49: =IFERROR(-AVERAGE(Base!O47:O49),"") -> 9.5500767 | I49: =IFERROR(AVERAGE(Base!P47:P49),"") -> 27.207206
A50: =Base!A50 -> 39478 | B50: =IFERROR(AVERAGE(Base!C48:C50)-Base!R50,"") -> 38.06801 | C50: =IFERROR(AVERAGE(Base!G48:G50)-Base!R50,"") -> 0.58571429 | D50: =IFERROR(AVERAGE(Base!H48:H50)-Base!R50,"") -> 2.5190476 | E50: 2.8068754 | F50: =IFERROR(AVERAGE(Base!K48:K50),"") -> 0.019811821 | G50: =IFERROR(AVERAGE(Base!M48:M50)*AVERAGE(Base!$F$13:F50),"") -> -0.70151602 | H50: =IFERROR(-AVERAGE(Base!O48:O50),"") -> 10.695456 | I50: =IFERROR(AVERAGE(Base!P48:P50),"") -> 17.334825
... A150: =Base!A150 -> 42521 | B150: =IFERROR(AVERAGE(Base!C148:C150)-Base!R150,"") -> -2.4208266 | C150: =IFERROR(AVERAGE(Base!G148:G150)-Base!R150,"") -> -2.975 | D150: =IFERROR(AVERAGE(Base!H148:H150)-Base!R150,"") -> 2.3583333 | E150: 5.9469064 | F150: =IFERROR(AVERAGE(Base!K148:K150),"") -> -3.7018662 | G150: =IFERROR(AVERAGE(Base!M148:M150)*AVERAGE(Base!$F$13:F150),"") -> 3.746536 | H150: =IFERROR(-AVERAGE(Base!O148:O150),"") -> -13.413016 | I150: =IFERROR(AVERAGE(Base!P148:P150),"") -> -28.687181
A151: =Base!A151 -> 42551 | B151: =IFERROR(AVERAGE(Base!C149:C151)-Base!R151,"") -> -6.6721835 | C151: =IFERROR(AVERAGE(Base!G149:G151)-Base!R151,"") -> -4.9033333 | D151: =IFERROR(AVERAGE(Base!H149:H151)-Base!R151,"") -> 0.89666667 | E151: =IFERROR(AVERAGE(Base!I149:I151)-AVERAGE(Base!S92:S151),"") -> 20.621486 | F151: =IFERROR(AVERAGE(Base!K149:K151),"") -> -5.1509271 | G151: =IFERROR(AVERAGE(Base!M149:M151)*AVERAGE(Base!$F$13:F151),"") -> 2.9440551 | H151: =IFERROR(-AVERAGE(Base!O149:O151),"") -> -13.22839 | I151: =IFERROR(AVERAGE(Base!P149:P151),"") -> -33.106183
A152: =Base!A152 -> 42582 | B152: =IFERROR(AVERAGE(Base!C150:C152)-Base!R152,"") -> -7.2441583 | C152: =IFERROR(AVERAGE(Base!G150:G152)-Base!R152,"") -> -5.6316667 | D152: =IFERROR(AVERAGE(Base!H150:H152)-Base!R152,"") -> 0.86833333 | E152: =IFERROR(AVERAGE(Base!I150:I152)-AVERAGE(Base!S93:S152),"") -> 22.477804 | F152: =IFERROR(AVERAGE(Base!K150:K152),"") -> -5.6670138 | G152: =IFERROR(AVERAGE(Base!M150:M152)*AVERAGE(Base!$F$13:F152),"") -> 3.3684205 | H152: =IFERROR(-AVERAGE(Base!O150:O152),"") -> -14.715944 | I152: =IFERROR(AVERAGE(Base!P150:P152),"") -> -39.032972
A153: =Base!A153 -> 42613 | B153: =IFERROR(AVERAGE(Base!C151:C153)-Base!R153,"") -> -4.1633279 | C153: =IFERROR(AVERAGE(Base!G151:G153)-Base!R153,"") -> -5.06 | D153: =IFERROR(AVERAGE(Base!H151:H153)-Base!R153,"") -> 0.94 | E153: =IFERROR(AVERAGE(Base!I151:I153)-AVERAGE(Base!S94:S153),"") -> 22.366907 | F153: =IFERROR(AVERAGE(Base!K151:K153),"") -> -4.5954827 | G153: =IFERROR(AVERAGE(Base!M151:M153)*AVERAGE(Base!$F$13:F153),"") -> 4.5665578 | H153: =IFERROR(-AVERAGE(Base!O151:O153),"") -> -15.867559 | I153: =IFERROR(AVERAGE(Base!P151:P153),"") -> -36.671446
A154: =Base!A154 -> 42643 | B154: =IFERROR(AVERAGE(Base!C152:C154)-Base!R154,"") -> -0.63954948 | C154: =IFERROR(AVERAGE(Base!G152:G154)-Base!R154,"") -> -3.8983333 | D154: =IFERROR(AVERAGE(Base!H152:H154)-Base!R154,"") -> 1.2683333 | E154: =IFERROR(AVERAGE(Base!I152:I154)-AVERAGE(Base!S95:S154),"") -> 20.870196 | F154: =IFERROR(AVERAGE(Base!K152:K154),"") -> -3.5621588 | G154: =IFERROR(AVERAGE(Base!M152:M154)*AVERAGE(Base!$F$13:F154),"") -> 5.68047 | H154: =IFERROR(-AVERAGE(Base!O152:O154),"") -> -14.415986 | I154: =IFERROR(AVERAGE(Base!P152:P154),"") -> -24.088957
A155: =Base!A155 -> 42674 | B155: =IFERROR(AVERAGE(Base!C153:C155)-Base!R155,"") -> 0.95550949 | C155: =IFERROR(AVERAGE(Base!G153:G155)-Base!R155,"") -> -3.3033333 | D155: =IFERROR(AVERAGE(Base!H153:H155)-Base!R155,"") -> 1.7966667 | E155: =IFERROR(AVERAGE(Base!I153:I155)-AVERAGE(Base!S96:S155),"") -> 20.263338 | F155: =IFERROR(AVERAGE(Base!K153:K155),"") -> -3.7721457 | G155: =IFERROR(AVERAGE(Base!M153:M155)*AVERAGE(Base!$F$13:F155),"") -> 5.9869446 | H155: =IFERROR(-AVERAGE(Base!O153:O155),"") -> -11.352614 | I155: =IFERROR(AVERAGE(Base!P153:P155),"") -> -6.7445131
A156: =Base!A156 -> 42704 | B156: =IFERROR(AVERAGE(Base!C154:C156)-Base!R156,"") -> 4.026451 | C156: =IFERROR(AVERAGE(Base!G154:G156)-Base!R156,"") -> -2.775 | D156: =IFERROR(AVERAGE(Base!H154:H156)-Base!R156,"") -> 2.5916667 | E156: =IFERROR(AVERAGE(Base!I154:I156)-AVERAGE(Base!S97:S156),"") -> 19.673072 | F156: =IFERROR(AVERAGE(Base!K154:K156),"") -> -4.4210333 | G156: =IFERROR(AVERAGE(Base!M154:M156)*AVERAGE(Base!$F$13:F156),"") -> 6.2983995 | H156: =IFERROR(-AVERAGE(Base!O154:O156),"") -> -7.9758106 | I156: =IFERROR(AVERAGE(Base!P154:P156),"") -> 1.8513271
A157: =Base!A157 -> 42735 | B157: =IFERROR(AVERAGE(Base!C155:C157)-Base!R157,"") -> 16.72098 | C157: =IFERROR(AVERAGE(Base!G155:G157)-Base!R157,"") -> -1.5966667 | D157: =IFERROR(AVERAGE(Base!H155:H157)-Base!R157,"") -> 3.9033333 | E157: =IFERROR(AVERAGE(Base!I155:I157)-AVERAGE(Base!S98:S157),"") -> 17.23501 | F157: =IFERROR(AVERAGE(Base!K155:K157),"") -> -5.7414647 | G157: =IFERROR(AVERAGE(Base!M155:M157)*AVERAGE(Base!$F$13:F157),"") -> 3.5131008 | H157: =IFERROR(-AVERAGE(Base!O155:O157),"") -> -6.3526411 | I157: =IFERROR(AVERAGE(Base!P155:P157),"") -> 9.7921102
A158: =Base!A158 -> 42766 | B158: =IFERROR(AVERAGE(Base!C156:C158)-Base!R158,"") -> 22.314471 | C158: =IFERROR(AVERAGE(Base!G156:G158)-Base!R158,"") -> 0.34833333 | D158: =IFERROR(AVERAGE(Base!H156:H158)-Base!R158,"") -> 4.4816667 | E158: =IFERROR(AVERAGE(Base!I156:I158)-AVERAGE(Base!S99:S158),"") -> 13.063393 | F158: =IFERROR(AVERAGE(Base!K156:K158),"") -> -5.9787633 | G158: =IFERROR(AVERAGE(Base!M156:M158)*AVERAGE(Base!$F$13:F158),"") -> 1.103828 | H158: =IFERROR(-AVERAGE(Base!O156:O158),"") -> -5.6622528 | I158: =IFERROR(AVERAGE(Base!P156:P158),"") -> 8.1151674
A159: =Base!A159 -> 42794 | B159: =IFERROR(AVERAGE(Base!C157:C159)-Base!R159,"") -> 13.493058 | C159: =IFERROR(AVERAGE(Base!G157:G159)-Base!R159,"") -> 0.32666667 | D159: =IFERROR(AVERAGE(Base!H157:H159)-Base!R159,"") -> 3.2933333 | E159: =IFERROR(AVERAGE(Base!I157:I159)-AVERAGE(Base!S100:S159),"") -> 9.2103253 | F159: =IFERROR(AVERAGE(Base!K157:K159),"") -> -6.1825174 | G159: =IFERROR(AVERAGE(Base!M157:M159)*AVERAGE(Base!$F$13:F159),"") -> -2.6785451 | H159: =IFERROR(-AVERAGE(Base!O157:O159),"") -> -5.7004035 | I159: =IFERROR(AVERAGE(Base!P157:P159),"") -> 5.447653
A160: =Base!A160 -> 42825 | B160: =IFERROR(AVERAGE(Base!C158:C160)-Base!R160,"") -> 2.7358234 | C160: =IFERROR(AVERAGE(Base!G158:G160)-Base!R160,"") -> 0.61 | D160: =IFERROR(AVERAGE(Base!H158:H160)-Base!R160,"") -> 2.5433333 | E160: =IFERROR(AVERAGE(Base!I158:I160)-AVERAGE(Base!S101:S160),"") -> 7.6609039 | F160: =IFERROR(AVERAGE(Base!K158:K160),"") -> -6.1462535 | G160: =IFERROR(AVERAGE(Base!M158:M160)*AVERAGE(Base!$F$13:F160),"") -> -3.7734826 | H160: =IFERROR(-AVERAGE(Base!O158:O160),"") -> -6.048569 | I160: =IFERROR(AVERAGE(Base!P158:P160),"") -> -0.85518291
A161: =Base!A161 -> 42855 | B161: =IFERROR(AVERAGE(Base!C159:C161)-Base!R161,"") -> 0.12416916 | C161: =IFERROR(AVERAGE(Base!G159:G161)-Base!R161,"") -> -0.10666667 | D161: =IFERROR(AVERAGE(Base!H159:H161)-Base!R161,"") -> 2.1933333 | E161: =IFERROR(AVERAGE(Base!I159:I161)-AVERAGE(Base!S102:S161),"") -> 7.0204976 | F161: =IFERROR(AVERAGE(Base!K159:K161),"") -> -8.7058869 | G161: =IFERROR(AVERAGE(Base!M159:M161)*AVERAGE(Base!$F$13:F161),"") -> -4.4045843 | H161: =IFERROR(-AVERAGE(Base!O159:O161),"") -> -5.4129024 | I161: =IFERROR(AVERAGE(Base!P159:P161),"") -> -7.4128986
A162: =Base!A162 -> 42886 | B162: =IFERROR(AVERAGE(Base!C160:C162)-Base!R162,"") -> 2.7699922 | C162: =IFERROR(AVERAGE(Base!G160:G162)-Base!R162,"") -> 1.11 | D162: =IFERROR(AVERAGE(Base!H160:H162)-Base!R162,"") -> 3.1433333 | E162: =IFERROR(AVERAGE(Base!I160:I162)-AVERAGE(Base!S103:S162),"") -> 5.4642035 | F162: =IFERROR(AVERAGE(Base!K160:K162),"") -> -8.5715113 | G162: =IFERROR(AVERAGE(Base!M160:M162)*AVERAGE(Base!$F$13:F162),"") -> -2.8853345 | H162: =IFERROR(-AVERAGE(Base!O160:O162),"") -> -3.4968552 | I162: =IFERROR(AVERAGE(Base!P160:P162),"") -> -4.1411101
... A273: =Base!A273 -> 46265 | B273: =IFERROR(AVERAGE(Base!C271:C273)-Base!R273,"") -> 14.4175 | C273: =IFERROR(AVERAGE(Base!G271:G273)-Base!R273,"") -> -0.005 | D273: =IFERROR(AVERAGE(Base!H271:H273)-Base!R273,"") -> -1.205 | E273: =IFERROR(AVERAGE(Base!I271:I273)-AVERAGE(Base!S214:S273),"") -> -33.340833 | F273: =IFERROR(AVERAGE(Base!K271:K273),"") -> 19.25292 | G273: =IFERROR(AVERAGE(Base!M271:M273)*AVERAGE(Base!$F$13:F273),"") -> -2.2773342 | H273: =IFERROR(-AVERAGE(Base!O271:O273),"") -> 2.0846704 | I273: =IFERROR(AVERAGE(Base!P271:P273),"") -> 146.52398
...

Sheet Senal
A1: Fecha | B1: z Exp | C1: z EMAE | D1: z EMAE Transp | E1: z IPC Transp | F1: z Prod. petroleo | G1: z ITCRM | H1: z Invent. | I1: z Crack | J1: w Exp | K1: w EMAE | L1: w EMAE Transp | M1: w IPC Transp | N1: w Prod. petroleo | O1: w ITCRM | P1: w Invent. | Q1: w Crack | R1: MEDIANA (score) | S1: |score| | T1: Umbral | U1: Senal | V1: Posicion cruda (clip +-1) | W1: Score EW (media, comparacion)
A2: =Base!A2 -> 38017
A3: =Base!A3 -> 38046
A4: =Base!A4 -> 38077
A5: =Base!A5 -> 38107
A6: =Base!A6 -> 38138
A7: =Base!A7 -> 38168
A8: =Base!A8 -> 38199
A9: =Base!A9 -> 38230
A10: =Base!A10 -> 38260
A11: =Base!A11 -> 38291
A12: =Base!A12 -> 38321
A13: =Base!A13 -> 38352
... A38: =Base!A38 -> 39113
A39: =Base!A39 -> 39141 | B39: =IF(COUNT(Transf!B$39:B39)<36,"",(Transf!B39-AVERAGE(Transf!B$39:B39))/STDEV(Transf!B$39:B39)) | C39: =IF(COUNT(Transf!C$39:C39)<36,"",(Transf!C39-AVERAGE(Transf!C$39:C39))/STDEV(Transf!C$39:C39)) | D39: =IF(COUNT(Transf!D$39:D39)<36,"",(Transf!D39-AVERAGE(Transf!D$39:D39))/STDEV(Transf!D$39:D39)) | E39: =IF(COUNT(Transf!E$39:E39)<36,"",(Transf!E39-AVERAGE(Transf!E$39:E39))/STDEV(Transf!E$39:E39)) | F39: =IF(COUNT(Transf!F$39:F39)<36,"",(Transf!F39-AVERAGE(Transf!F$39:F39))/STDEV(Transf!F$39:F39)) | G39: =IF(COUNT(Transf!G$39:G39)<36,"",(Transf!G39-AVERAGE(Transf!G$39:G39))/STDEV(Transf!G$39:G39)) | H39: =IF(COUNT(Transf!H$39:H39)<36,"",(Transf!H39-AVERAGE(Transf!H$39:H39))/STDEV(Transf!H$39:H39)) | I39: =IF(COUNT(Transf!I$39:I39)<36,"",(Transf!I39-AVERAGE(Transf!I$39:I39))/STDEV(Transf!I$39:I39))
A40: =Base!A40 -> 39172 | B40: =IF(COUNT(Transf!B$39:B40)<36,"",(Transf!B40-AVERAGE(Transf!B$39:B40))/STDEV(Transf!B$39:B40)) | C40: =IF(COUNT(Transf!C$39:C40)<36,"",(Transf!C40-AVERAGE(Transf!C$39:C40))/STDEV(Transf!C$39:C40)) | D40: =IF(COUNT(Transf!D$39:D40)<36,"",(Transf!D40-AVERAGE(Transf!D$39:D40))/STDEV(Transf!D$39:D40)) | E40: =IF(COUNT(Transf!E$39:E40)<36,"",(Transf!E40-AVERAGE(Transf!E$39:E40))/STDEV(Transf!E$39:E40)) | F40: =IF(COUNT(Transf!F$39:F40)<36,"",(Transf!F40-AVERAGE(Transf!F$39:F40))/STDEV(Transf!F$39:F40)) | G40: =IF(COUNT(Transf!G$39:G40)<36,"",(Transf!G40-AVERAGE(Transf!G$39:G40))/STDEV(Transf!G$39:G40)) | H40: =IF(COUNT(Transf!H$39:H40)<36,"",(Transf!H40-AVERAGE(Transf!H$39:H40))/STDEV(Transf!H$39:H40)) | I40: =IF(COUNT(Transf!I$39:I40)<36,"",(Transf!I40-AVERAGE(Transf!I$39:I40))/STDEV(Transf!I$39:I40))
A41: =Base!A41 -> 39202 | B41: =IF(COUNT(Transf!B$39:B41)<36,"",(Transf!B41-AVERAGE(Transf!B$39:B41))/STDEV(Transf!B$39:B41)) | C41: =IF(COUNT(Transf!C$39:C41)<36,"",(Transf!C41-AVERAGE(Transf!C$39:C41))/STDEV(Transf!C$39:C41)) | D41: =IF(COUNT(Transf!D$39:D41)<36,"",(Transf!D41-AVERAGE(Transf!D$39:D41))/STDEV(Transf!D$39:D41)) | E41: =IF(COUNT(Transf!E$39:E41)<36,"",(Transf!E41-AVERAGE(Transf!E$39:E41))/STDEV(Transf!E$39:E41)) | F41: =IF(COUNT(Transf!F$39:F41)<36,"",(Transf!F41-AVERAGE(Transf!F$39:F41))/STDEV(Transf!F$39:F41)) | G41: =IF(COUNT(Transf!G$39:G41)<36,"",(Transf!G41-AVERAGE(Transf!G$39:G41))/STDEV(Transf!G$39:G41)) | H41: =IF(COUNT(Transf!H$39:H41)<36,"",(Transf!H41-AVERAGE(Transf!H$39:H41))/STDEV(Transf!H$39:H41)) | I41: =IF(COUNT(Transf!I$39:I41)<36,"",(Transf!I41-AVERAGE(Transf!I$39:I41))/STDEV(Transf!I$39:I41))
A42: =Base!A42 -> 39233 | B42: =IF(COUNT(Transf!B$39:B42)<36,"",(Transf!B42-AVERAGE(Transf!B$39:B42))/STDEV(Transf!B$39:B42)) | C42: =IF(COUNT(Transf!C$39:C42)<36,"",(Transf!C42-AVERAGE(Transf!C$39:C42))/STDEV(Transf!C$39:C42)) | D42: =IF(COUNT(Transf!D$39:D42)<36,"",(Transf!D42-AVERAGE(Transf!D$39:D42))/STDEV(Transf!D$39:D42)) | E42: =IF(COUNT(Transf!E$39:E42)<36,"",(Transf!E42-AVERAGE(Transf!E$39:E42))/STDEV(Transf!E$39:E42)) | F42: =IF(COUNT(Transf!F$39:F42)<36,"",(Transf!F42-AVERAGE(Transf!F$39:F42))/STDEV(Transf!F$39:F42)) | G42: =IF(COUNT(Transf!G$39:G42)<36,"",(Transf!G42-AVERAGE(Transf!G$39:G42))/STDEV(Transf!G$39:G42)) | H42: =IF(COUNT(Transf!H$39:H42)<36,"",(Transf!H42-AVERAGE(Transf!H$39:H42))/STDEV(Transf!H$39:H42)) | I42: =IF(COUNT(Transf!I$39:I42)<36,"",(Transf!I42-AVERAGE(Transf!I$39:I42))/STDEV(Transf!I$39:I42))
A43: =Base!A43 -> 39263 | B43: =IF(COUNT(Transf!B$39:B43)<36,"",(Transf!B43-AVERAGE(Transf!B$39:B43))/STDEV(Transf!B$39:B43)) | C43: =IF(COUNT(Transf!C$39:C43)<36,"",(Transf!C43-AVERAGE(Transf!C$39:C43))/STDEV(Transf!C$39:C43)) | D43: =IF(COUNT(Transf!D$39:D43)<36,"",(Transf!D43-AVERAGE(Transf!D$39:D43))/STDEV(Transf!D$39:D43)) | E43: =IF(COUNT(Transf!E$39:E43)<36,"",(Transf!E43-AVERAGE(Transf!E$39:E43))/STDEV(Transf!E$39:E43)) | F43: =IF(COUNT(Transf!F$39:F43)<36,"",(Transf!F43-AVERAGE(Transf!F$39:F43))/STDEV(Transf!F$39:F43)) | G43: =IF(COUNT(Transf!G$39:G43)<36,"",(Transf!G43-AVERAGE(Transf!G$39:G43))/STDEV(Transf!G$39:G43)) | H43: =IF(COUNT(Transf!H$39:H43)<36,"",(Transf!H43-AVERAGE(Transf!H$39:H43))/STDEV(Transf!H$39:H43)) | I43: =IF(COUNT(Transf!I$39:I43)<36,"",(Transf!I43-AVERAGE(Transf!I$39:I43))/STDEV(Transf!I$39:I43))
A44: =Base!A44 -> 39294 | B44: =IF(COUNT(Transf!B$39:B44)<36,"",(Transf!B44-AVERAGE(Transf!B$39:B44))/STDEV(Transf!B$39:B44)) | C44: =IF(COUNT(Transf!C$39:C44)<36,"",(Transf!C44-AVERAGE(Transf!C$39:C44))/STDEV(Transf!C$39:C44)) | D44: =IF(COUNT(Transf!D$39:D44)<36,"",(Transf!D44-AVERAGE(Transf!D$39:D44))/STDEV(Transf!D$39:D44)) | E44: =IF(COUNT(Transf!E$39:E44)<36,"",(Transf!E44-AVERAGE(Transf!E$39:E44))/STDEV(Transf!E$39:E44)) | F44: =IF(COUNT(Transf!F$39:F44)<36,"",(Transf!F44-AVERAGE(Transf!F$39:F44))/STDEV(Transf!F$39:F44)) | G44: =IF(COUNT(Transf!G$39:G44)<36,"",(Transf!G44-AVERAGE(Transf!G$39:G44))/STDEV(Transf!G$39:G44)) | H44: =IF(COUNT(Transf!H$39:H44)<36,"",(Transf!H44-AVERAGE(Transf!H$39:H44))/STDEV(Transf!H$39:H44)) | I44: =IF(COUNT(Transf!I$39:I44)<36,"",(Transf!I44-AVERAGE(Transf!I$39:I44))/STDEV(Transf!I$39:I44))
A45: =Base!A45 -> 39325 | B45: =IF(COUNT(Transf!B$39:B45)<36,"",(Transf!B45-AVERAGE(Transf!B$39:B45))/STDEV(Transf!B$39:B45)) | C45: =IF(COUNT(Transf!C$39:C45)<36,"",(Transf!C45-AVERAGE(Transf!C$39:C45))/STDEV(Transf!C$39:C45)) | D45: =IF(COUNT(Transf!D$39:D45)<36,"",(Transf!D45-AVERAGE(Transf!D$39:D45))/STDEV(Transf!D$39:D45)) | E45: =IF(COUNT(Transf!E$39:E45)<36,"",(Transf!E45-AVERAGE(Transf!E$39:E45))/STDEV(Transf!E$39:E45)) | F45: =IF(COUNT(Transf!F$39:F45)<36,"",(Transf!F45-AVERAGE(Transf!F$39:F45))/STDEV(Transf!F$39:F45)) | G45: =IF(COUNT(Transf!G$39:G45)<36,"",(Transf!G45-AVERAGE(Transf!G$39:G45))/STDEV(Transf!G$39:G45)) | H45: =IF(COUNT(Transf!H$39:H45)<36,"",(Transf!H45-AVERAGE(Transf!H$39:H45))/STDEV(Transf!H$39:H45)) | I45: =IF(COUNT(Transf!I$39:I45)<36,"",(Transf!I45-AVERAGE(Transf!I$39:I45))/STDEV(Transf!I$39:I45))
A46: =Base!A46 -> 39355 | B46: =IF(COUNT(Transf!B$39:B46)<36,"",(Transf!B46-AVERAGE(Transf!B$39:B46))/STDEV(Transf!B$39:B46)) | C46: =IF(COUNT(Transf!C$39:C46)<36,"",(Transf!C46-AVERAGE(Transf!C$39:C46))/STDEV(Transf!C$39:C46)) | D46: =IF(COUNT(Transf!D$39:D46)<36,"",(Transf!D46-AVERAGE(Transf!D$39:D46))/STDEV(Transf!D$39:D46)) | E46: =IF(COUNT(Transf!E$39:E46)<36,"",(Transf!E46-AVERAGE(Transf!E$39:E46))/STDEV(Transf!E$39:E46)) | F46: =IF(COUNT(Transf!F$39:F46)<36,"",(Transf!F46-AVERAGE(Transf!F$39:F46))/STDEV(Transf!F$39:F46)) | G46: =IF(COUNT(Transf!G$39:G46)<36,"",(Transf!G46-AVERAGE(Transf!G$39:G46))/STDEV(Transf!G$39:G46)) | H46: =IF(COUNT(Transf!H$39:H46)<36,"",(Transf!H46-AVERAGE(Transf!H$39:H46))/STDEV(Transf!H$39:H46)) | I46: =IF(COUNT(Transf!I$39:I46)<36,"",(Transf!I46-AVERAGE(Transf!I$39:I46))/STDEV(Transf!I$39:I46))
A47: =Base!A47 -> 39386 | B47: =IF(COUNT(Transf!B$39:B47)<36,"",(Transf!B47-AVERAGE(Transf!B$39:B47))/STDEV(Transf!B$39:B47)) | C47: =IF(COUNT(Transf!C$39:C47)<36,"",(Transf!C47-AVERAGE(Transf!C$39:C47))/STDEV(Transf!C$39:C47)) | D47: =IF(COUNT(Transf!D$39:D47)<36,"",(Transf!D47-AVERAGE(Transf!D$39:D47))/STDEV(Transf!D$39:D47)) | E47: =IF(COUNT(Transf!E$39:E47)<36,"",(Transf!E47-AVERAGE(Transf!E$39:E47))/STDEV(Transf!E$39:E47)) | F47: =IF(COUNT(Transf!F$39:F47)<36,"",(Transf!F47-AVERAGE(Transf!F$39:F47))/STDEV(Transf!F$39:F47)) | G47: =IF(COUNT(Transf!G$39:G47)<36,"",(Transf!G47-AVERAGE(Transf!G$39:G47))/STDEV(Transf!G$39:G47)) | H47: =IF(COUNT(Transf!H$39:H47)<36,"",(Transf!H47-AVERAGE(Transf!H$39:H47))/STDEV(Transf!H$39:H47)) | I47: =IF(COUNT(Transf!I$39:I47)<36,"",(Transf!I47-AVERAGE(Transf!I$39:I47))/STDEV(Transf!I$39:I47))
A48: =Base!A48 -> 39416 | B48: =IF(COUNT(Transf!B$39:B48)<36,"",(Transf!B48-AVERAGE(Transf!B$39:B48))/STDEV(Transf!B$39:B48)) | C48: =IF(COUNT(Transf!C$39:C48)<36,"",(Transf!C48-AVERAGE(Transf!C$39:C48))/STDEV(Transf!C$39:C48)) | D48: =IF(COUNT(Transf!D$39:D48)<36,"",(Transf!D48-AVERAGE(Transf!D$39:D48))/STDEV(Transf!D$39:D48)) | E48: =IF(COUNT(Transf!E$39:E48)<36,"",(Transf!E48-AVERAGE(Transf!E$39:E48))/STDEV(Transf!E$39:E48)) | F48: =IF(COUNT(Transf!F$39:F48)<36,"",(Transf!F48-AVERAGE(Transf!F$39:F48))/STDEV(Transf!F$39:F48)) | G48: =IF(COUNT(Transf!G$39:G48)<36,"",(Transf!G48-AVERAGE(Transf!G$39:G48))/STDEV(Transf!G$39:G48)) | H48: =IF(COUNT(Transf!H$39:H48)<36,"",(Transf!H48-AVERAGE(Transf!H$39:H48))/STDEV(Transf!H$39:H48)) | I48: =IF(COUNT(Transf!I$39:I48)<36,"",(Transf!I48-AVERAGE(Transf!I$39:I48))/STDEV(Transf!I$39:I48))
A49: =Base!A49 -> 39447 | B49: =IF(COUNT(Transf!B$39:B49)<36,"",(Transf!B49-AVERAGE(Transf!B$39:B49))/STDEV(Transf!B$39:B49)) | C49: =IF(COUNT(Transf!C$39:C49)<36,"",(Transf!C49-AVERAGE(Transf!C$39:C49))/STDEV(Transf!C$39:C49)) | D49: =IF(COUNT(Transf!D$39:D49)<36,"",(Transf!D49-AVERAGE(Transf!D$39:D49))/STDEV(Transf!D$39:D49)) | E49: =IF(COUNT(Transf!E$39:E49)<36,"",(Transf!E49-AVERAGE(Transf!E$39:E49))/STDEV(Transf!E$39:E49)) | F49: =IF(COUNT(Transf!F$39:F49)<36,"",(Transf!F49-AVERAGE(Transf!F$39:F49))/STDEV(Transf!F$39:F49)) | G49: =IF(COUNT(Transf!G$39:G49)<36,"",(Transf!G49-AVERAGE(Transf!G$39:G49))/STDEV(Transf!G$39:G49)) | H49: =IF(COUNT(Transf!H$39:H49)<36,"",(Transf!H49-AVERAGE(Transf!H$39:H49))/STDEV(Transf!H$39:H49)) | I49: =IF(COUNT(Transf!I$39:I49)<36,"",(Transf!I49-AVERAGE(Transf!I$39:I49))/STDEV(Transf!I$39:I49))
A50: =Base!A50 -> 39478 | B50: =IF(COUNT(Transf!B$39:B50)<36,"",(Transf!B50-AVERAGE(Transf!B$39:B50))/STDEV(Transf!B$39:B50)) | C50: =IF(COUNT(Transf!C$39:C50)<36,"",(Transf!C50-AVERAGE(Transf!C$39:C50))/STDEV(Transf!C$39:C50)) | D50: =IF(COUNT(Transf!D$39:D50)<36,"",(Transf!D50-AVERAGE(Transf!D$39:D50))/STDEV(Transf!D$39:D50)) | E50: =IF(COUNT(Transf!E$39:E50)<36,"",(Transf!E50-AVERAGE(Transf!E$39:E50))/STDEV(Transf!E$39:E50)) | F50: =IF(COUNT(Transf!F$39:F50)<36,"",(Transf!F50-AVERAGE(Transf!F$39:F50))/STDEV(Transf!F$39:F50)) | G50: =IF(COUNT(Transf!G$39:G50)<36,"",(Transf!G50-AVERAGE(Transf!G$39:G50))/STDEV(Transf!G$39:G50)) | H50: =IF(COUNT(Transf!H$39:H50)<36,"",(Transf!H50-AVERAGE(Transf!H$39:H50))/STDEV(Transf!H$39:H50)) | I50: =IF(COUNT(Transf!I$39:I50)<36,"",(Transf!I50-AVERAGE(Transf!I$39:I50))/STDEV(Transf!I$39:I50))
... A73: =Base!A73 -> 40178 | B73: =IF(COUNT(Transf!B$39:B73)<36,"",(Transf!B73-AVERAGE(Transf!B$39:B73))/STDEV(Transf!B$39:B73)) | C73: =IF(COUNT(Transf!C$39:C73)<36,"",(Transf!C73-AVERAGE(Transf!C$39:C73))/STDEV(Transf!C$39:C73)) | D73: =IF(COUNT(Transf!D$39:D73)<36,"",(Transf!D73-AVERAGE(Transf!D$39:D73))/STDEV(Transf!D$39:D73)) | E73: =IF(COUNT(Transf!E$39:E73)<36,"",(Transf!E73-AVERAGE(Transf!E$39:E73))/STDEV(Transf!E$39:E73)) | F73: =IF(COUNT(Transf!F$39:F73)<36,"",(Transf!F73-AVERAGE(Transf!F$39:F73))/STDEV(Transf!F$39:F73)) | G73: =IF(COUNT(Transf!G$39:G73)<36,"",(Transf!G73-AVERAGE(Transf!G$39:G73))/STDEV(Transf!G$39:G73)) | H73: =IF(COUNT(Transf!H$39:H73)<36,"",(Transf!H73-AVERAGE(Transf!H$39:H73))/STDEV(Transf!H$39:H73)) | I73: =IF(COUNT(Transf!I$39:I73)<36,"",(Transf!I73-AVERAGE(Transf!I$39:I73))/STDEV(Transf!I$39:I73))
A74: =Base!A74 -> 40209 | B74: =IF(COUNT(Transf!B$39:B74)<36,"",(Transf!B74-AVERAGE(Transf!B$39:B74))/STDEV(Transf!B$39:B74)) -> 0.12776213 | C74: =IF(COUNT(Transf!C$39:C74)<36,"",(Transf!C74-AVERAGE(Transf!C$39:C74))/STDEV(Transf!C$39:C74)) -> 0.44708068 | D74: =IF(COUNT(Transf!D$39:D74)<36,"",(Transf!D74-AVERAGE(Transf!D$39:D74))/STDEV(Transf!D$39:D74)) -> 0.30254342 | E74: =IF(COUNT(Transf!E$39:E74)<36,"",(Transf!E74-AVERAGE(Transf!E$39:E74))/STDEV(Transf!E$39:E74)) -> -0.80858734 | F74: =IF(COUNT(Transf!F$39:F74)<36,"",(Transf!F74-AVERAGE(Transf!F$39:F74))/STDEV(Transf!F$39:F74)) -> -1.0406195 | G74: =IF(COUNT(Transf!G$39:G74)<36,"",(Transf!G74-AVERAGE(Transf!G$39:G74))/STDEV(Transf!G$39:G74)) -> 1.7412184 | H74: =IF(COUNT(Transf!H$39:H74)<36,"",(Transf!H74-AVERAGE(Transf!H$39:H74))/STDEV(Transf!H$39:H74)) -> 0.077778053 | I74: =IF(COUNT(Transf!I$39:I74)<36,"",(Transf!I74-AVERAGE(Transf!I$39:I74))/STDEV(Transf!I$39:I74)) -> 0.98128025 | J74: =IF(B74="","",IF(COUNT(B$74:B74)<60,B74,MEDIAN(QUARTILE(B$74:B74,1)-1.5*(QUARTILE(B$74:B74,3)-QUARTILE(B$74:B74,1)),B74,QUARTILE(B$74:B74,3)+1.5*(QUARTILE(B$74:B74,3)-QUARTILE(B$74:B74,1))))) -> 0.12776213 | K74: =IF(C74="","",IF(COUNT(C$74:C74)<60,C74,MEDIAN(QUARTILE(C$74:C74,1)-1.5*(QUARTILE(C$74:C74,3)-QUARTILE(C$74:C74,1)),C74,QUARTILE(C$74:C74,3)+1.5*(QUARTILE(C$74:C74,3)-QUARTILE(C$74:C74,1))))) -> 0.44708068 | L74: =IF(D74="","",IF(COUNT(D$74:D74)<60,D74,MEDIAN(QUARTILE(D$74:D74,1)-1.5*(QUARTILE(D$74:D74,3)-QUARTILE(D$74:D74,1)),D74,QUARTILE(D$74:D74,3)+1.5*(QUARTILE(D$74:D74,3)-QUARTILE(D$74:D74,1))))) -> 0.30254342 | M74: =IF(E74="","",IF(COUNT(E$74:E74)<60,E74,MEDIAN(QUARTILE(E$74:E74,1)-1.5*(QUARTILE(E$74:E74,3)-QUARTILE(E$74:E74,1)),E74,QUARTILE(E$74:E74,3)+1.5*(QUARTILE(E$74:E74,3)-QUARTILE(E$74:E74,1))))) -> -0.80858734 | N74: =IF(F74="","",IF(COUNT(F$74:F74)<60,F74,MEDIAN(QUARTILE(F$74:F74,1)-1.5*(QUARTILE(F$74:F74,3)-QUARTILE(F$74:F74,1)),F74,QUARTILE(F$74:F74,3)+1.5*(QUARTILE(F$74:F74,3)-QUARTILE(F$74:F74,1))))) -> -1.0406195 | O74: =IF(G74="","",IF(COUNT(G$74:G74)<60,G74,MEDIAN(QUARTILE(G$74:G74,1)-1.5*(QUARTILE(G$74:G74,3)-QUARTILE(G$74:G74,1)),G74,QUARTILE(G$74:G74,3)+1.5*(QUARTILE(G$74:G74,3)-QUARTILE(G$74:G74,1))))) -> 1.7412184 | P74: =IF(H74="","",IF(COUNT(H$74:H74)<60,H74,MEDIAN(QUARTILE(H$74:H74,1)-1.5*(QUARTILE(H$74:H74,3)-QUARTILE(H$74:H74,1)),H74,QUARTILE(H$74:H74,3)+1.5*(QUARTILE(H$74:H74,3)-QUARTILE(H$74:H74,1))))) -> 0.077778053 | Q74: =IF(I74="","",IF(COUNT(I$74:I74)<60,I74,MEDIAN(QUARTILE(I$74:I74,1)-1.5*(QUARTILE(I$74:I74,3)-QUARTILE(I$74:I74,1)),I74,QUARTILE(I$74:I74,3)+1.5*(QUARTILE(I$74:I74,3)-QUARTILE(I$74:I74,1))))) -> 0.98128025 | R74: =IF(J74="","",MEDIAN(J74:Q74)) -> 0.21515277 | S74: =IF(R74="","",ABS(R74)) -> 0.21515277 | T74: =IF(COUNT(S$74:S73)<60,"",MEDIAN(S$74:S73)) | U74: =IF(R74="","",IF(T74="",0,IF(S74>=T74,R74,0))) -> 0 | V74: =IF(U74="","",MEDIAN(-1,U74,1)) -> 0 | W74: =IF(J74="","",AVERAGE(J74:Q74)) -> 0.22855702
A75: =Base!A75 -> 40237 | B75: =IF(COUNT(Transf!B$39:B75)<36,"",(Transf!B75-AVERAGE(Transf!B$39:B75))/STDEV(Transf!B$39:B75)) -> 0.14215922 | C75: =IF(COUNT(Transf!C$39:C75)<36,"",(Transf!C75-AVERAGE(Transf!C$39:C75))/STDEV(Transf!C$39:C75)) -> 0.61817763 | D75: =IF(COUNT(Transf!D$39:D75)<36,"",(Transf!D75-AVERAGE(Transf!D$39:D75))/STDEV(Transf!D$39:D75)) -> 0.42039626 | E75: =IF(COUNT(Transf!E$39:E75)<36,"",(Transf!E75-AVERAGE(Transf!E$39:E75))/STDEV(Transf!E$39:E75)) -> -0.32302304 | F75: =IF(COUNT(Transf!F$39:F75)<36,"",(Transf!F75-AVERAGE(Transf!F$39:F75))/STDEV(Transf!F$39:F75)) -> -0.62638274 | G75: =IF(COUNT(Transf!G$39:G75)<36,"",(Transf!G75-AVERAGE(Transf!G$39:G75))/STDEV(Transf!G$39:G75)) -> 1.1043792 | H75: =IF(COUNT(Transf!H$39:H75)<36,"",(Transf!H75-AVERAGE(Transf!H$39:H75))/STDEV(Transf!H$39:H75)) -> 0.3860933 | I75: =IF(COUNT(Transf!I$39:I75)<36,"",(Transf!I75-AVERAGE(Transf!I$39:I75))/STDEV(Transf!I$39:I75)) -> -0.24801986 | J75: =IF(B75="","",IF(COUNT(B$74:B75)<60,B75,MEDIAN(QUARTILE(B$74:B75,1)-1.5*(QUARTILE(B$74:B75,3)-QUARTILE(B$74:B75,1)),B75,QUARTILE(B$74:B75,3)+1.5*(QUARTILE(B$74:B75,3)-QUARTILE(B$74:B75,1))))) -> 0.14215922 | K75: =IF(C75="","",IF(COUNT(C$74:C75)<60,C75,MEDIAN(QUARTILE(C$74:C75,1)-1.5*(QUARTILE(C$74:C75,3)-QUARTILE(C$74:C75,1)),C75,QUARTILE(C$74:C75,3)+1.5*(QUARTILE(C$74:C75,3)-QUARTILE(C$74:C75,1))))) -> 0.61817763 | L75: =IF(D75="","",IF(COUNT(D$74:D75)<60,D75,MEDIAN(QUARTILE(D$74:D75,1)-1.5*(QUARTILE(D$74:D75,3)-QUARTILE(D$74:D75,1)),D75,QUARTILE(D$74:D75,3)+1.5*(QUARTILE(D$74:D75,3)-QUARTILE(D$74:D75,1))))) -> 0.42039626 | M75: =IF(E75="","",IF(COUNT(E$74:E75)<60,E75,MEDIAN(QUARTILE(E$74:E75,1)-1.5*(QUARTILE(E$74:E75,3)-QUARTILE(E$74:E75,1)),E75,QUARTILE(E$74:E75,3)+1.5*(QUARTILE(E$74:E75,3)-QUARTILE(E$74:E75,1))))) -> -0.32302304 | N75: =IF(F75="","",IF(COUNT(F$74:F75)<60,F75,MEDIAN(QUARTILE(F$74:F75,1)-1.5*(QUARTILE(F$74:F75,3)-QUARTILE(F$74:F75,1)),F75,QUARTILE(F$74:F75,3)+1.5*(QUARTILE(F$74:F75,3)-QUARTILE(F$74:F75,1))))) -> -0.62638274 | O75: =IF(G75="","",IF(COUNT(G$74:G75)<60,G75,MEDIAN(QUARTILE(G$74:G75,1)-1.5*(QUARTILE(G$74:G75,3)-QUARTILE(G$74:G75,1)),G75,QUARTILE(G$74:G75,3)+1.5*(QUARTILE(G$74:G75,3)-QUARTILE(G$74:G75,1))))) -> 1.1043792 | P75: =IF(H75="","",IF(COUNT(H$74:H75)<60,H75,MEDIAN(QUARTILE(H$74:H75,1)-1.5*(QUARTILE(H$74:H75,3)-QUARTILE(H$74:H75,1)),H75,QUARTILE(H$74:H75,3)+1.5*(QUARTILE(H$74:H75,3)-QUARTILE(H$74:H75,1))))) -> 0.3860933 | Q75: =IF(I75="","",IF(COUNT(I$74:I75)<60,I75,MEDIAN(QUARTILE(I$74:I75,1)-1.5*(QUARTILE(I$74:I75,3)-QUARTILE(I$74:I75,1)),I75,QUARTILE(I$74:I75,3)+1.5*(QUARTILE(I$74:I75,3)-QUARTILE(I$74:I75,1))))) -> -0.24801986 | R75: =IF(J75="","",MEDIAN(J75:Q75)) -> 0.26412626 | S75: =IF(R75="","",ABS(R75)) -> 0.26412626 | T75: =IF(COUNT(S$74:S74)<60,"",MEDIAN(S$74:S74)) | U75: =IF(R75="","",IF(T75="",0,IF(S75>=T75,R75,0))) -> 0 | V75: =IF(U75="","",MEDIAN(-1,U75,1)) -> 0 | W75: =IF(J75="","",AVERAGE(J75:Q75)) -> 0.1842225
A76: =Base!A76 -> 40268 | B76: =IF(COUNT(Transf!B$39:B76)<36,"",(Transf!B76-AVERAGE(Transf!B$39:B76))/STDEV(Transf!B$39:B76)) -> 0.095872919 | C76: =IF(COUNT(Transf!C$39:C76)<36,"",(Transf!C76-AVERAGE(Transf!C$39:C76))/STDEV(Transf!C$39:C76)) -> 0.94127035 | D76: =IF(COUNT(Transf!D$39:D76)<36,"",(Transf!D76-AVERAGE(Transf!D$39:D76))/STDEV(Transf!D$39:D76)) -> 0.63517301 | E76: =IF(COUNT(Transf!E$39:E76)<36,"",(Transf!E76-AVERAGE(Transf!E$39:E76))/STDEV(Transf!E$39:E76)) -> 0.013792284 | F76: =IF(COUNT(Transf!F$39:F76)<36,"",(Transf!F76-AVERAGE(Transf!F$39:F76))/STDEV(Transf!F$39:F76)) -> -0.39725613 | G76: =IF(COUNT(Transf!G$39:G76)<36,"",(Transf!G76-AVERAGE(Transf!G$39:G76))/STDEV(Transf!G$39:G76)) -> 0.62963729 | H76: =IF(COUNT(Transf!H$39:H76)<36,"",(Transf!H76-AVERAGE(Transf!H$39:H76))/STDEV(Transf!H$39:H76)) -> 0.52302727 | I76: =IF(COUNT(Transf!I$39:I76)<36,"",(Transf!I76-AVERAGE(Transf!I$39:I76))/STDEV(Transf!I$39:I76)) -> -0.47229098 | J76: =IF(B76="","",IF(COUNT(B$74:B76)<60,B76,MEDIAN(QUARTILE(B$74:B76,1)-1.5*(QUARTILE(B$74:B76,3)-QUARTILE(B$74:B76,1)),B76,QUARTILE(B$74:B76,3)+1.5*(QUARTILE(B$74:B76,3)-QUARTILE(B$74:B76,1))))) -> 0.095872919 | K76: =IF(C76="","",IF(COUNT(C$74:C76)<60,C76,MEDIAN(QUARTILE(C$74:C76,1)-1.5*(QUARTILE(C$74:C76,3)-QUARTILE(C$74:C76,1)),C76,QUARTILE(C$74:C76,3)+1.5*(QUARTILE(C$74:C76,3)-QUARTILE(C$74:C76,1))))) -> 0.94127035 | L76: =IF(D76="","",IF(COUNT(D$74:D76)<60,D76,MEDIAN(QUARTILE(D$74:D76,1)-1.5*(QUARTILE(D$74:D76,3)-QUARTILE(D$74:D76,1)),D76,QUARTILE(D$74:D76,3)+1.5*(QUARTILE(D$74:D76,3)-QUARTILE(D$74:D76,1))))) -> 0.63517301 | M76: =IF(E76="","",IF(COUNT(E$74:E76)<60,E76,MEDIAN(QUARTILE(E$74:E76,1)-1.5*(QUARTILE(E$74:E76,3)-QUARTILE(E$74:E76,1)),E76,QUARTILE(E$74:E76,3)+1.5*(QUARTILE(E$74:E76,3)-QUARTILE(E$74:E76,1))))) -> 0.013792284 | N76: =IF(F76="","",IF(COUNT(F$74:F76)<60,F76,MEDIAN(QUARTILE(F$74:F76,1)-1.5*(QUARTILE(F$74:F76,3)-QUARTILE(F$74:F76,1)),F76,QUARTILE(F$74:F76,3)+1.5*(QUARTILE(F$74:F76,3)-QUARTILE(F$74:F76,1))))) -> -0.39725613 | O76: =IF(G76="","",IF(COUNT(G$74:G76)<60,G76,MEDIAN(QUARTILE(G$74:G76,1)-1.5*(QUARTILE(G$74:G76,3)-QUARTILE(G$74:G76,1)),G76,QUARTILE(G$74:G76,3)+1.5*(QUARTILE(G$74:G76,3)-QUARTILE(G$74:G76,1))))) -> 0.62963729 | P76: =IF(H76="","",IF(COUNT(H$74:H76)<60,H76,MEDIAN(QUARTILE(H$74:H76,1)-1.5*(QUARTILE(H$74:H76,3)-QUARTILE(H$74:H76,1)),H76,QUARTILE(H$74:H76,3)+1.5*(QUARTILE(H$74:H76,3)-QUARTILE(H$74:H76,1))))) -> 0.52302727 | Q76: =IF(I76="","",IF(COUNT(I$74:I76)<60,I76,MEDIAN(QUARTILE(I$74:I76,1)-1.5*(QUARTILE(I$74:I76,3)-QUARTILE(I$74:I76,1)),I76,QUARTILE(I$74:I76,3)+1.5*(QUARTILE(I$74:I76,3)-QUARTILE(I$74:I76,1))))) -> -0.47229098 | R76: =IF(J76="","",MEDIAN(J76:Q76)) -> 0.3094501 | S76: =IF(R76="","",ABS(R76)) -> 0.3094501 | T76: =IF(COUNT(S$74:S75)<60,"",MEDIAN(S$74:S75)) | U76: =IF(R76="","",IF(T76="",0,IF(S76>=T76,R76,0))) -> 0 | V76: =IF(U76="","",MEDIAN(-1,U76,1)) -> 0 | W76: =IF(J76="","",AVERAGE(J76:Q76)) -> 0.24615325
A77: =Base!A77 -> 40298 | B77: =IF(COUNT(Transf!B$39:B77)<36,"",(Transf!B77-AVERAGE(Transf!B$39:B77))/STDEV(Transf!B$39:B77)) -> 0.15317993 | C77: =IF(COUNT(Transf!C$39:C77)<36,"",(Transf!C77-AVERAGE(Transf!C$39:C77))/STDEV(Transf!C$39:C77)) -> 1.4287501 | D77: =IF(COUNT(Transf!D$39:D77)<36,"",(Transf!D77-AVERAGE(Transf!D$39:D77))/STDEV(Transf!D$39:D77)) -> 0.83829666 | E77: =IF(COUNT(Transf!E$39:E77)<36,"",(Transf!E77-AVERAGE(Transf!E$39:E77))/STDEV(Transf!E$39:E77)) -> 0.25527337 | F77: =IF(COUNT(Transf!F$39:F77)<36,"",(Transf!F77-AVERAGE(Transf!F$39:F77))/STDEV(Transf!F$39:F77)) -> -0.46198469 | G77: =IF(COUNT(Transf!G$39:G77)<36,"",(Transf!G77-AVERAGE(Transf!G$39:G77))/STDEV(Transf!G$39:G77)) -> 0.26376784 | H77: =IF(COUNT(Transf!H$39:H77)<36,"",(Transf!H77-AVERAGE(Transf!H$39:H77))/STDEV(Transf!H$39:H77)) -> 0.46675848 | I77: =IF(COUNT(Transf!I$39:I77)<36,"",(Transf!I77-AVERAGE(Transf!I$39:I77))/STDEV(Transf!I$39:I77)) -> 0.55170507 | J77: =IF(B77="","",IF(COUNT(B$74:B77)<60,B77,MEDIAN(QUARTILE(B$74:B77,1)-1.5*(QUARTILE(B$74:B77,3)-QUARTILE(B$74:B77,1)),B77,QUARTILE(B$74:B77,3)+1.5*(QUARTILE(B$74:B77,3)-QUARTILE(B$74:B77,1))))) -> 0.15317993 | K77: =IF(C77="","",IF(COUNT(C$74:C77)<60,C77,MEDIAN(QUARTILE(C$74:C77,1)-1.5*(QUARTILE(C$74:C77,3)-QUARTILE(C$74:C77,1)),C77,QUARTILE(C$74:C77,3)+1.5*(QUARTILE(C$74:C77,3)-QUARTILE(C$74:C77,1))))) -> 1.4287501 | L77: =IF(D77="","",IF(COUNT(D$74:D77)<60,D77,MEDIAN(QUARTILE(D$74:D77,1)-1.5*(QUARTILE(D$74:D77,3)-QUARTILE(D$74:D77,1)),D77,QUARTILE(D$74:D77,3)+1.5*(QUARTILE(D$74:D77,3)-QUARTILE(D$74:D77,1))))) -> 0.83829666 | M77: =IF(E77="","",IF(COUNT(E$74:E77)<60,E77,MEDIAN(QUARTILE(E$74:E77,1)-1.5*(QUARTILE(E$74:E77,3)-QUARTILE(E$74:E77,1)),E77,QUARTILE(E$74:E77,3)+1.5*(QUARTILE(E$74:E77,3)-QUARTILE(E$74:E77,1))))) -> 0.25527337 | N77: =IF(F77="","",IF(COUNT(F$74:F77)<60,F77,MEDIAN(QUARTILE(F$74:F77,1)-1.5*(QUARTILE(F$74:F77,3)-QUARTILE(F$74:F77,1)),F77,QUARTILE(F$74:F77,3)+1.5*(QUARTILE(F$74:F77,3)-QUARTILE(F$74:F77,1))))) -> -0.46198469 | O77: =IF(G77="","",IF(COUNT(G$74:G77)<60,G77,MEDIAN(QUARTILE(G$74:G77,1)-1.5*(QUARTILE(G$74:G77,3)-QUARTILE(G$74:G77,1)),G77,QUARTILE(G$74:G77,3)+1.5*(QUARTILE(G$74:G77,3)-QUARTILE(G$74:G77,1))))) -> 0.26376784 | P77: =IF(H77="","",IF(COUNT(H$74:H77)<60,H77,MEDIAN(QUARTILE(H$74:H77,1)-1.5*(QUARTILE(H$74:H77,3)-QUARTILE(H$74:H77,1)),H77,QUARTILE(H$74:H77,3)+1.5*(QUARTILE(H$74:H77,3)-QUARTILE(H$74:H77,1))))) -> 0.46675848 | Q77: =IF(I77="","",IF(COUNT(I$74:I77)<60,I77,MEDIAN(QUARTILE(I$74:I77,1)-1.5*(QUARTILE(I$74:I77,3)-QUARTILE(I$74:I77,1)),I77,QUARTILE(I$74:I77,3)+1.5*(QUARTILE(I$74:I77,3)-QUARTILE(I$74:I77,1))))) -> 0.55170507 | R77: =IF(J77="","",MEDIAN(J77:Q77)) -> 0.36526316 | S77: =IF(R77="","",ABS(R77)) -> 0.36526316 | T77: =IF(COUNT(S$74:S76)<60,"",MEDIAN(S$74:S76)) | U77: =IF(R77="","",IF(T77="",0,IF(S77>=T77,R77,0))) -> 0 | V77: =IF(U77="","",MEDIAN(-1,U77,1)) -> 0 | W77: =IF(J77="","",AVERAGE(J77:Q77)) -> 0.43696835
A78: =Base!A78 -> 40329 | B78: =IF(COUNT(Transf!B$39:B78)<36,"",(Transf!B78-AVERAGE(Transf!B$39:B78))/STDEV(Transf!B$39:B78)) -> 0.49048346 | C78: =IF(COUNT(Transf!C$39:C78)<36,"",(Transf!C78-AVERAGE(Transf!C$39:C78))/STDEV(Transf!C$39:C78)) -> 2.0697309 | D78: =IF(COUNT(Transf!D$39:D78)<36,"",(Transf!D78-AVERAGE(Transf!D$39:D78))/STDEV(Transf!D$39:D78)) -> 1.3230079 | E78: =IF(COUNT(Transf!E$39:E78)<36,"",(Transf!E78-AVERAGE(Transf!E$39:E78))/STDEV(Transf!E$39:E78)) -> 0.27282152 | F78: =IF(COUNT(Transf!F$39:F78)<36,"",(Transf!F78-AVERAGE(Transf!F$39:F78))/STDEV(Transf!F$39:F78)) -> -0.36389379 | G78: =IF(COUNT(Transf!G$39:G78)<36,"",(Transf!G78-AVERAGE(Transf!G$39:G78))/STDEV(Transf!G$39:G78)) -> -0.3543603 | H78: =IF(COUNT(Transf!H$39:H78)<36,"",(Transf!H78-AVERAGE(Transf!H$39:H78))/STDEV(Transf!H$39:H78)) -> 0.39306014 | I78: =IF(COUNT(Transf!I$39:I78)<36,"",(Transf!I78-AVERAGE(Transf!I$39:I78))/STDEV(Transf!I$39:I78)) -> 0.71515232 | J78: =IF(B78="","",IF(COUNT(B$74:B78)<60,B78,MEDIAN(QUARTILE(B$74:B78,1)-1.5*(QUARTILE(B$74:B78,3)-QUARTILE(B$74:B78,1)),B78,QUARTILE(B$74:B78,3)+1.5*(QUARTILE(B$74:B78,3)-QUARTILE(B$74:B78,1))))) -> 0.49048346 | K78: =IF(C78="","",IF(COUNT(C$74:C78)<60,C78,MEDIAN(QUARTILE(C$74:C78,1)-1.5*(QUARTILE(C$74:C78,3)-QUARTILE(C$74:C78,1)),C78,QUARTILE(C$74:C78,3)+1.5*(QUARTILE(C$74:C78,3)-QUARTILE(C$74:C78,1))))) -> 2.0697309 | L78: =IF(D78="","",IF(COUNT(D$74:D78)<60,D78,MEDIAN(QUARTILE(D$74:D78,1)-1.5*(QUARTILE(D$74:D78,3)-QUARTILE(D$74:D78,1)),D78,QUARTILE(D$74:D78,3)+1.5*(QUARTILE(D$74:D78,3)-QUARTILE(D$74:D78,1))))) -> 1.3230079 | M78: =IF(E78="","",IF(COUNT(E$74:E78)<60,E78,MEDIAN(QUARTILE(E$74:E78,1)-1.5*(QUARTILE(E$74:E78,3)-QUARTILE(E$74:E78,1)),E78,QUARTILE(E$74:E78,3)+1.5*(QUARTILE(E$74:E78,3)-QUARTILE(E$74:E78,1))))) -> 0.27282152 | N78: =IF(F78="","",IF(COUNT(F$74:F78)<60,F78,MEDIAN(QUARTILE(F$74:F78,1)-1.5*(QUARTILE(F$74:F78,3)-QUARTILE(F$74:F78,1)),F78,QUARTILE(F$74:F78,3)+1.5*(QUARTILE(F$74:F78,3)-QUARTILE(F$74:F78,1))))) -> -0.36389379 | O78: =IF(G78="","",IF(COUNT(G$74:G78)<60,G78,MEDIAN(QUARTILE(G$74:G78,1)-1.5*(QUARTILE(G$74:G78,3)-QUARTILE(G$74:G78,1)),G78,QUARTILE(G$74:G78,3)+1.5*(QUARTILE(G$74:G78,3)-QUARTILE(G$74:G78,1))))) -> -0.3543603 | P78: =IF(H78="","",IF(COUNT(H$74:H78)<60,H78,MEDIAN(QUARTILE(H$74:H78,1)-1.5*(QUARTILE(H$74:H78,3)-QUARTILE(H$74:H78,1)),H78,QUARTILE(H$74:H78,3)+1.5*(QUARTILE(H$74:H78,3)-QUARTILE(H$74:H78,1))))) -> 0.39306014 | Q78: =IF(I78="","",IF(COUNT(I$74:I78)<60,I78,MEDIAN(QUARTILE(I$74:I78,1)-1.5*(QUARTILE(I$74:I78,3)-QUARTILE(I$74:I78,1)),I78,QUARTILE(I$74:I78,3)+1.5*(QUARTILE(I$74:I78,3)-QUARTILE(I$74:I78,1))))) -> 0.71515232 | R78: =IF(J78="","",MEDIAN(J78:Q78)) -> 0.4417718 | S78: =IF(R78="","",ABS(R78)) -> 0.4417718 | T78: =IF(COUNT(S$74:S77)<60,"",MEDIAN(S$74:S77)) | U78: =IF(R78="","",IF(T78="",0,IF(S78>=T78,R78,0))) -> 0 | V78: =IF(U78="","",MEDIAN(-1,U78,1)) -> 0 | W78: =IF(J78="","",AVERAGE(J78:Q78)) -> 0.56825027
A79: =Base!A79 -> 40359 | B79: =IF(COUNT(Transf!B$39:B79)<36,"",(Transf!B79-AVERAGE(Transf!B$39:B79))/STDEV(Transf!B$39:B79)) -> 0.65029673 | C79: =IF(COUNT(Transf!C$39:C79)<36,"",(Transf!C79-AVERAGE(Transf!C$39:C79))/STDEV(Transf!C$39:C79)) -> 2.2549017 | D79: =IF(COUNT(Transf!D$39:D79)<36,"",(Transf!D79-AVERAGE(Transf!D$39:D79))/STDEV(Transf!D$39:D79)) -> 1.4797173 | E79: =IF(COUNT(Transf!E$39:E79)<36,"",(Transf!E79-AVERAGE(Transf!E$39:E79))/STDEV(Transf!E$39:E79)) -> 0.30294043 | F79: =IF(COUNT(Transf!F$39:F79)<36,"",(Transf!F79-AVERAGE(Transf!F$39:F79))/STDEV(Transf!F$39:F79)) -> -0.10042702 | G79: =IF(COUNT(Transf!G$39:G79)<36,"",(Transf!G79-AVERAGE(Transf!G$39:G79))/STDEV(Transf!G$39:G79)) -> -0.79609446 | H79: =IF(COUNT(Transf!H$39:H79)<36,"",(Transf!H79-AVERAGE(Transf!H$39:H79))/STDEV(Transf!H$39:H79)) -> 0.20660033 | I79: =IF(COUNT(Transf!I$39:I79)<36,"",(Transf!I79-AVERAGE(Transf!I$39:I79))/STDEV(Transf!I$39:I79)) -> 0.73333163 | J79: =IF(B79="","",IF(COUNT(B$74:B79)<60,B79,MEDIAN(QUARTILE(B$74:B79,1)-1.5*(QUARTILE(B$74:B79,3)-QUARTILE(B$74:B79,1)),B79,QUARTILE(B$74:B79,3)+1.5*(QUARTILE(B$74:B79,3)-QUARTILE(B$74:B79,1))))) -> 0.65029673 | K79: =IF(C79="","",IF(COUNT(C$74:C79)<60,C79,MEDIAN(QUARTILE(C$74:C79,1)-1.5*(QUARTILE(C$74:C79,3)-QUARTILE(C$74:C79,1)),C79,QUARTILE(C$74:C79,3)+1.5*(QUARTILE(C$74:C79,3)-QUARTILE(C$74:C79,1))))) -> 2.2549017 | L79: =IF(D79="","",IF(COUNT(D$74:D79)<60,D79,MEDIAN(QUARTILE(D$74:D79,1)-1.5*(QUARTILE(D$74:D79,3)-QUARTILE(D$74:D79,1)),D79,QUARTILE(D$74:D79,3)+1.5*(QUARTILE(D$74:D79,3)-QUARTILE(D$74:D79,1))))) -> 1.4797173 | M79: =IF(E79="","",IF(COUNT(E$74:E79)<60,E79,MEDIAN(QUARTILE(E$74:E79,1)-1.5*(QUARTILE(E$74:E79,3)-QUARTILE(E$74:E79,1)),E79,QUARTILE(E$74:E79,3)+1.5*(QUARTILE(E$74:E79,3)-QUARTILE(E$74:E79,1))))) -> 0.30294043 | N79: =IF(F79="","",IF(COUNT(F$74:F79)<60,F79,MEDIAN(QUARTILE(F$74:F79,1)-1.5*(QUARTILE(F$74:F79,3)-QUARTILE(F$74:F79,1)),F79,QUARTILE(F$74:F79,3)+1.5*(QUARTILE(F$74:F79,3)-QUARTILE(F$74:F79,1))))) -> -0.10042702 | O79: =IF(G79="","",IF(COUNT(G$74:G79)<60,G79,MEDIAN(QUARTILE(G$74:G79,1)-1.5*(QUARTILE(G$74:G79,3)-QUARTILE(G$74:G79,1)),G79,QUARTILE(G$74:G79,3)+1.5*(QUARTILE(G$74:G79,3)-QUARTILE(G$74:G79,1))))) -> -0.79609446 | P79: =IF(H79="","",IF(COUNT(H$74:H79)<60,H79,MEDIAN(QUARTILE(H$74:H79,1)-1.5*(QUARTILE(H$74:H79,3)-QUARTILE(H$74:H79,1)),H79,QUARTILE(H$74:H79,3)+1.5*(QUARTILE(H$74:H79,3)-QUARTILE(H$74:H79,1))))) -> 0.20660033 | Q79: =IF(I79="","",IF(COUNT(I$74:I79)<60,I79,MEDIAN(QUARTILE(I$74:I79,1)-1.5*(QUARTILE(I$74:I79,3)-QUARTILE(I$74:I79,1)),I79,QUARTILE(I$74:I79,3)+1.5*(QUARTILE(I$74:I79,3)-QUARTILE(I$74:I79,1))))) -> 0.73333163 | R79: =IF(J79="","",MEDIAN(J79:Q79)) -> 0.47661858 | S79: =IF(R79="","",ABS(R79)) -> 0.47661858 | T79: =IF(COUNT(S$74:S78)<60,"",MEDIAN(S$74:S78)) | U79: =IF(R79="","",IF(T79="",0,IF(S79>=T79,R79,0))) -> 0 | V79: =IF(U79="","",MEDIAN(-1,U79,1)) -> 0 | W79: =IF(J79="","",AVERAGE(J79:Q79)) -> 0.59140834
A80: =Base!A80 -> 40390 | B80: =IF(COUNT(Transf!B$39:B80)<36,"",(Transf!B80-AVERAGE(Transf!B$39:B80))/STDEV(Transf!B$39:B80)) -> 0.61818762 | C80: =IF(COUNT(Transf!C$39:C80)<36,"",(Transf!C80-AVERAGE(Transf!C$39:C80))/STDEV(Transf!C$39:C80)) -> 1.9130825 | D80: =IF(COUNT(Transf!D$39:D80)<36,"",(Transf!D80-AVERAGE(Transf!D$39:D80))/STDEV(Transf!D$39:D80)) -> 1.4626672 | E80: =IF(COUNT(Transf!E$39:E80)<36,"",(Transf!E80-AVERAGE(Transf!E$39:E80))/STDEV(Transf!E$39:E80)) -> 0.39573701 | F80: =IF(COUNT(Transf!F$39:F80)<36,"",(Transf!F80-AVERAGE(Transf!F$39:F80))/STDEV(Transf!F$39:F80)) -> 0.097164576 | G80: =IF(COUNT(Transf!G$39:G80)<36,"",(Transf!G80-AVERAGE(Transf!G$39:G80))/STDEV(Transf!G$39:G80)) -> -1.2183716 | H80: =IF(COUNT(Transf!H$39:H80)<36,"",(Transf!H80-AVERAGE(Transf!H$39:H80))/STDEV(Transf!H$39:H80)) -> -0.0084980961 | I80: =IF(COUNT(Transf!I$39:I80)<36,"",(Transf!I80-AVERAGE(Transf!I$39:I80))/STDEV(Transf!I$39:I80)) -> -0.076315586 | J80: =IF(B80="","",IF(COUNT(B$74:B80)<60,B80,MEDIAN(QUARTILE(B$74:B80,1)-1.5*(QUARTILE(B$74:B80,3)-QUARTILE(B$74:B80,1)),B80,QUARTILE(B$74:B80,3)+1.5*(QUARTILE(B$74:B80,3)-QUARTILE(B$74:B80,1))))) -> 0.61818762 | K80: =IF(C80="","",IF(COUNT(C$74:C80)<60,C80,MEDIAN(QUARTILE(C$74:C80,1)-1.5*(QUARTILE(C$74:C80,3)-QUARTILE(C$74:C80,1)),C80,QUARTILE(C$74:C80,3)+1.5*(QUARTILE(C$74:C80,3)-QUARTILE(C$74:C80,1))))) -> 1.9130825 | L80: =IF(D80="","",IF(COUNT(D$74:D80)<60,D80,MEDIAN(QUARTILE(D$74:D80,1)-1.5*(QUARTILE(D$74:D80,3)-QUARTILE(D$74:D80,1)),D80,QUARTILE(D$74:D80,3)+1.5*(QUARTILE(D$74:D80,3)-QUARTILE(D$74:D80,1))))) -> 1.4626672 | M80: =IF(E80="","",IF(COUNT(E$74:E80)<60,E80,MEDIAN(QUARTILE(E$74:E80,1)-1.5*(QUARTILE(E$74:E80,3)-QUARTILE(E$74:E80,1)),E80,QUARTILE(E$74:E80,3)+1.5*(QUARTILE(E$74:E80,3)-QUARTILE(E$74:E80,1))))) -> 0.39573701 | N80: =IF(F80="","",IF(COUNT(F$74:F80)<60,F80,MEDIAN(QUARTILE(F$74:F80,1)-1.5*(QUARTILE(F$74:F80,3)-QUARTILE(F$74:F80,1)),F80,QUARTILE(F$74:F80,3)+1.5*(QUARTILE(F$74:F80,3)-QUARTILE(F$74:F80,1))))) -> 0.097164576 | O80: =IF(G80="","",IF(COUNT(G$74:G80)<60,G80,MEDIAN(QUARTILE(G$74:G80,1)-1.5*(QUARTILE(G$74:G80,3)-QUARTILE(G$74:G80,1)),G80,QUARTILE(G$74:G80,3)+1.5*(QUARTILE(G$74:G80,3)-QUARTILE(G$74:G80,1))))) -> -1.2183716 | P80: =IF(H80="","",IF(COUNT(H$74:H80)<60,H80,MEDIAN(QUARTILE(H$74:H80,1)-1.5*(QUARTILE(H$74:H80,3)-QUARTILE(H$74:H80,1)),H80,QUARTILE(H$74:H80,3)+1.5*(QUARTILE(H$74:H80,3)-QUARTILE(H$74:H80,1))))) -> -0.0084980961 | Q80: =IF(I80="","",IF(COUNT(I$74:I80)<60,I80,MEDIAN(QUARTILE(I$74:I80,1)-1.5*(QUARTILE(I$74:I80,3)-QUARTILE(I$74:I80,1)),I80,QUARTILE(I$74:I80,3)+1.5*(QUARTILE(I$74:I80,3)-QUARTILE(I$74:I80,1))))) -> -0.076315586 | R80: =IF(J80="","",MEDIAN(J80:Q80)) -> 0.24645079 | S80: =IF(R80="","",ABS(R80)) -> 0.24645079 | T80: =IF(COUNT(S$74:S79)<60,"",MEDIAN(S$74:S79)) | U80: =IF(R80="","",IF(T80="",0,IF(S80>=T80,R80,0))) -> 0 | V80: =IF(U80="","",MEDIAN(-1,U80,1)) -> 0 | W80: =IF(J80="","",AVERAGE(J80:Q80)) -> 0.3979567
A81: =Base!A81 -> 40421 | B81: =IF(COUNT(Transf!B$39:B81)<36,"",(Transf!B81-AVERAGE(Transf!B$39:B81))/STDEV(Transf!B$39:B81)) -> 0.9064662 | C81: =IF(COUNT(Transf!C$39:C81)<36,"",(Transf!C81-AVERAGE(Transf!C$39:C81))/STDEV(Transf!C$39:C81)) -> 1.4639292 | D81: =IF(COUNT(Transf!D$39:D81)<36,"",(Transf!D81-AVERAGE(Transf!D$39:D81))/STDEV(Transf!D$39:D81)) -> 1.2431972 | E81: =IF(COUNT(Transf!E$39:E81)<36,"",(Transf!E81-AVERAGE(Transf!E$39:E81))/STDEV(Transf!E$39:E81)) -> 0.38496056 | F81: =IF(COUNT(Transf!F$39:F81)<36,"",(Transf!F81-AVERAGE(Transf!F$39:F81))/STDEV(Transf!F$39:F81)) -> 1.2599404 | G81: =IF(COUNT(Transf!G$39:G81)<36,"",(Transf!G81-AVERAGE(Transf!G$39:G81))/STDEV(Transf!G$39:G81)) -> -1.251393 | H81: =IF(COUNT(Transf!H$39:H81)<36,"",(Transf!H81-AVERAGE(Transf!H$39:H81))/STDEV(Transf!H$39:H81)) -> -0.22214889 | I81: =IF(COUNT(Transf!I$39:I81)<36,"",(Transf!I81-AVERAGE(Transf!I$39:I81))/STDEV(Transf!I$39:I81)) -> 0.19708213 | J81: =IF(B81="","",IF(COUNT(B$74:B81)<60,B81,MEDIAN(QUARTILE(B$74:B81,1)-1.5*(QUARTILE(B$74:B81,3)-QUARTILE(B$74:B81,1)),B81,QUARTILE(B$74:B81,3)+1.5*(QUARTILE(B$74:B81,3)-QUARTILE(B$74:B81,1))))) -> 0.9064662 | K81: =IF(C81="","",IF(COUNT(C$74:C81)<60,C81,MEDIAN(QUARTILE(C$74:C81,1)-1.5*(QUARTILE(C$74:C81,3)-QUARTILE(C$74:C81,1)),C81,QUARTILE(C$74:C81,3)+1.5*(QUARTILE(C$74:C81,3)-QUARTILE(C$74:C81,1))))) -> 1.4639292 | L81: =IF(D81="","",IF(COUNT(D$74:D81)<60,D81,MEDIAN(QUARTILE(D$74:D81,1)-1.5*(QUARTILE(D$74:D81,3)-QUARTILE(D$74:D81,1)),D81,QUARTILE(D$74:D81,3)+1.5*(QUARTILE(D$74:D81,3)-QUARTILE(D$74:D81,1))))) -> 1.2431972 | M81: =IF(E81="","",IF(COUNT(E$74:E81)<60,E81,MEDIAN(QUARTILE(E$74:E81,1)-1.5*(QUARTILE(E$74:E81,3)-QUARTILE(E$74:E81,1)),E81,QUARTILE(E$74:E81,3)+1.5*(QUARTILE(E$74:E81,3)-QUARTILE(E$74:E81,1))))) -> 0.38496056 | N81: =IF(F81="","",IF(COUNT(F$74:F81)<60,F81,MEDIAN(QUARTILE(F$74:F81,1)-1.5*(QUARTILE(F$74:F81,3)-QUARTILE(F$74:F81,1)),F81,QUARTILE(F$74:F81,3)+1.5*(QUARTILE(F$74:F81,3)-QUARTILE(F$74:F81,1))))) -> 1.2599404 | O81: =IF(G81="","",IF(COUNT(G$74:G81)<60,G81,MEDIAN(QUARTILE(G$74:G81,1)-1.5*(QUARTILE(G$74:G81,3)-QUARTILE(G$74:G81,1)),G81,QUARTILE(G$74:G81,3)+1.5*(QUARTILE(G$74:G81,3)-QUARTILE(G$74:G81,1))))) -> -1.251393 | P81: =IF(H81="","",IF(COUNT(H$74:H81)<60,H81,MEDIAN(QUARTILE(H$74:H81,1)-1.5*(QUARTILE(H$74:H81,3)-QUARTILE(H$74:H81,1)),H81,QUARTILE(H$74:H81,3)+1.5*(QUARTILE(H$74:H81,3)-QUARTILE(H$74:H81,1))))) -> -0.22214889 | Q81: =IF(I81="","",IF(COUNT(I$74:I81)<60,I81,MEDIAN(QUARTILE(I$74:I81,1)-1.5*(QUARTILE(I$74:I81,3)-QUARTILE(I$74:I81,1)),I81,QUARTILE(I$74:I81,3)+1.5*(QUARTILE(I$74:I81,3)-QUARTILE(I$74:I81,1))))) -> 0.19708213 | R81: =IF(J81="","",MEDIAN(J81:Q81)) -> 0.64571338 | S81: =IF(R81="","",ABS(R81)) -> 0.64571338 | T81: =IF(COUNT(S$74:S80)<60,"",MEDIAN(S$74:S80)) | U81: =IF(R81="","",IF(T81="",0,IF(S81>=T81,R81,0))) -> 0 | V81: =IF(U81="","",MEDIAN(-1,U81,1)) -> 0 | W81: =IF(J81="","",AVERAGE(J81:Q81)) -> 0.49775423
